Workbook

Sheet load by month
B1: 1 | AA1: 2 | AZ1: 3 | BX1: 4 | CV1: 5 | DT1: 6 | ER1: 7 | FP1: 8 | GN1: 9 | HL1: 10 | IJ1: 11 | JH1: 12
A2: macro-region/residents | B2: 0 | C2: 1 | D2: 2 | E2: 3 | F2: 4 | G2: 5 | H2: 6 | I2: 7 | J2: 8 | K2: 9 | L2: 10 | M2: 11 | N2: 12 | O2: 13 | P2: 14 | Q2: 15 | R2: 16 | S2: 17 | T2: 18 | U2: 19 | V2: 20 | W2: 21 | X2: 22 | Y2: 23 | AA2: 0 | AB2: 1 | AC2: 2 | AD2: 3 | AE2: 4 | AF2: 5 | AG2: 6 | AH2: 7 | AI2: 8 | AJ2: 9 | AK2: 10 | AL2: 11 | AM2: 12 | AN2: 13 | AO2: 14 | AP2: 15 | AQ2: 16 | AR2: 17 | AS2: 18 | AT2: 19 | AU2: 20 | AV2: 21 | AW2: 22 | AX2: 23 | AZ2: 0 | BA2: 1 | BB2: 2 | BC2: 3 | BD2: 4 | BE2: 5 | BF2: 6 | BG2: 7 | BH2: 8 | BI2: 9 | BJ2: 10 | BK2: 11 | BL2: 12 | BM2: 13 | BN2: 14 | BO2: 15 | BP2: 16 | BQ2: 17 | BR2: 18 | BS2: 19 | BT2: 20 | BU2: 21 | BV2: 22 | BW2: 23 | BX2: 0 | BY2: 1 | BZ2: 2 | CA2: 3 | CB2: 4 | CC2: 5 | CD2: 6 | CE2: 7 | CF2: 8 | CG2: 9 | CH2: 10 | CI2: 11 | CJ2: 12 | CK2: 13 | CL2: 14 | CM2: 15 | CN2: 16 | CO2: 17 | CP2: 18 | CQ2: 19 | CR2: 20 | CS2: 21 | CT2: 22 | CU2: 23 | CV2: 0 | CW2: 1 | CX2: 2 | CY2: 3 | CZ2: 4 | DA2: 5 | DB2: 6 | DC2: 7 | DD2: 8 | DE2: 9 | DF2: 10 | DG2: 11 | DH2: 12 | DI2: 13 | DJ2: 14 | DK2: 15 | DL2: 16 | DM2: 17 | DN2: 18 | DO2: 19 | DP2: 20 | DQ2: 21 | DR2: 22 | DS2: 23 | DT2: 0 | DU2: 1 | DV2: 2 | DW2: 3 | DX2: 4 | DY2: 5 | DZ2: 6 | EA2: 7 | EB2: 8 | EC2: 9 | ED2: 10 | EE2: 11 | EF2: 12 | EG2: 13 | EH2: 14 | EI2: 15 | EJ2: 16 | EK2: 17 | EL2: 18 | EM2: 19 | EN2: 20 | EO2: 21 | EP2: 22 | EQ2: 23 | ER2: 0 | ES2: 1 | ET2: 2 | EU2: 3 | EV2: 4 | EW2: 5 | EX2: 6 | EY2: 7 | EZ2: 8 | FA2: 9 | FB2: 10 | FC2: 11 | FD2: 12 | FE2: 13 | FF2: 14 | FG2: 15 | FH2: 16 | FI2: 17 | FJ2: 18 | FK2: 19 | FL2: 20 | FM2: 21 | FN2: 22 | FO2: 23 | FP2: 0 | FQ2: 1 | FR2: 2 | FS2: 3 | FT2: 4 | FU2: 5 | FV2: 6 | FW2: 7 | FX2: 8 | FY2: 9 | FZ2: 10 | GA2: 11 | GB2: 12 | GC2: 13 | GD2: 14 | GE2: 15 | GF2: 16 | GG2: 17 | GH2: 18 | GI2: 19 | GJ2: 20 | GK2: 21 | GL2: 22 | GM2: 23 | GN2: 0 | GO2: 1 | GP2: 2 | GQ2: 3 | GR2: 4 | GS2: 5 | GT2: 6 | GU2: 7 | GV2: 8 | GW2: 9 | GX2: 10 | GY2: 11 | GZ2: 12 | HA2: 13 | HB2: 14 | HC2: 15 | HD2: 16 | HE2: 17 | HF2: 18 | HG2: 19 | HH2: 20 | HI2: 21 | HJ2: 22 | HK2: 23 | HL2: 0 | HM2: 1 | HN2: 2 | HO2: 3 | HP2: 4 | HQ2: 5 | HR2: 6 | HS2: 7 | HT2: 8 | HU2: 9 | HV2: 10 | HW2: 11 | HX2: 12 | HY2: 13 | HZ2: 14 | IA2: 15 | IB2: 16 | IC2: 17 | ID2: 18 | IE2: 19 | IF2: 20 | IG2: 21 | IH2: 22 | II2: 23 | IJ2: 0 | IK2: 1 | IL2: 2 | IM2: 3 | IN2: 4 | IO2: 5 | IP2: 6 | IQ2: 7 | IR2: 8 | IS2: 9 | IT2: 10 | IU2: 11 | IV2: 12 | IW2: 13 | IX2: 14 | IY2: 15 | IZ2: 16 | JA2: 17 | JB2: 18 | JC2: 19 | JD2: 20 | JE2: 21 | JF2: 22 | JG2: 23 | JH2: 0 | JI2: 1 | JJ2: 2 | JK2: 3 | JL2: 4 | JM2: 5 | JN2: 6 | JO2: 7 | JP2: 8 | JQ2: 9 | JR2: 10 | JS2: 11 | JT2: 12 | JU2: 13 | JV2: 14 | JW2: 15 | JX2: 16 | JY2: 17 | JZ2: 18 | KA2: 19 | KB2: 20 | KC2: 21 | KD2: 22 | KE2: 23
A3: 1 | B3: 0.40604583 | C3: 0.33629167 | D3: 0.28327361 | E3: 0.25505556 | F3: 0.24204722 | G3: 0.23967361 | H3: 0.255875 | I3: 0.30037778 | J3: 0.36664722 | K3: 0.41427778 | L3: 0.45181944 | M3: 0.46338611 | N3: 0.48299444 | O3: 0.51168333 | P3: 0.48565278 | Q3: 0.47393889 | R3: 0.44896389 | S3: 0.45670417 | T3: 0.52845139 | U3: 0.62846389 | V3: 0.70529861 | W3: 0.65827222 | X3: 0.60021389 | Y3: 0.50129444 | AA3: 0.37470278 | AB3: 0.30872639 | AC3: 0.26007639 | AD3: 0.23411389 | AE3: 0.22298889 | AF3: 0.22180556 | AG3: 0.23901944 | AH3: 0.28842639 | AI3: 0.3553625 | AJ3: 0.39254722 | AK3: 0.42104028 | AL3: 0.42096667 | AM3: 0.43399444 | AN3: 0.45799444 | AO3: 0.43240556 | AP3: 0.41923056 | AQ3: 0.39067639 | AR3: 0.38634861 | AS3: 0.44096944 | AT3: 0.56763889 | AU3: 0.65829028 | AV3: 0.61359722 | AW3: 0.55709444 | AX3: 0.46442778 | AZ3: 0.35646806 | BA3: 0.29170833 | BB3: 0.24581944 | BC3: 0.20468056 | BD3: 0.21312778 | BE3: 0.21124167 | BF3: 0.22712361 | BG3: 0.271125 | BH3: 0.32718889 | BI3: 0.36078194 | BJ3: 0.38595694 | BK3: 0.38581667 | BL3: 0.40121528 | BM3: 0.42819583 | BN3: 0.40649583 | BO3: 0.39342222 | BP3: 0.36417917 | BQ3: 0.35104306 | BR3: 0.38555833 | BS3: 0.497925 | BT3: 0.62027361 | BU3: 0.58708333 | BV3: 0.53425694 | BW3: 0.44468333 | BX3: 0.34074306 | BY3: 0.2745 | BZ3: 0.22898333 | CA3: 0.20626806 | CB3: 0.19627222 | CC3: 0.19369444 | CD3: 0.20466944 | CE3: 0.23876944 | CF3: 0.28866806 | CG3: 0.32585139 | CH3: 0.35314861 | CI3: 0.35599583 | CJ3: 0.37109306 | CK3: 0.39679167 | CL3: 0.37322222 | CM3: 0.36099306 | CN3: 0.33423333 | CO3: 0.31607917 | CP3: 0.32617778 | CQ3: 0.39071111 | CR3: 0.5071375 | CS3: 0.53106667 | CT3: 0.50010417 | CU3: 0.42206667 | CV3: 0.33017917 | CW3: 0.27403472 | CX3: 0.23174167 | CY3: 0.20909444 | CZ3: 0.19834861 | DA3: 0.19344167 | DB3: 0.19890972 | DC3: 0.2168875 | DD3: 0.25764167 | DE3: 0.29420833 | DF3: 0.31917222 | DG3: 0.32258611 | DH3: 0.33860417 | DI3: 0.36618333 | DJ3: 0.35222361 | DK3: 0.34540833 | DL3: 0.32307917 | DM3: 0.30595139 | DN3: 0.31058194 | DO3: 0.35866111 | DP3: 0.45036667 | DQ3: 0.46826111 | DR3: 0.46291667 | DS3: 0.40329028 | DT3: 0.39203056 | DU3: 0.32297917 | DV3: 0.27805833 | DW3: 0.25244028 | DX3: 0.23819583 | DY3: 0.22964722 | DZ3: 0.22763472 | EA3: 0.23194861 | EB3: 0.25857083 | EC3: 0.29053472 | ED3: 0.31240833 | EE3: 0.32066667 | EF3: 0.34092778 | EG3: 0.37463889 | EH3: 0.37621806 | EI3: 0.37638056 | EJ3: 0.36164306 | EK3: 0.35186111 | EL3: 0.35964167 | EM3: 0.40018194 | EN3: 0.47519722 | EO3: 0.49089861 | EP3: 0.49224583 | EQ3: 0.45885417 | ER3: 0.49260139 | ES3: 0.41364722 | ET3: 0.36192083 | EU3: 0.33011806 | EV3: 0.30967778 | EW3: 0.29501528 | EX3: 0.28645694 | EY3: 0.27905139 | EZ3: 0.29031389 | FA3: 0.31279306 | FB3: 0.33456528 | FC3: 0.35097778 | FD3: 0.38336528 | FE3: 0.43220833 | FF3: 0.4524125 | FG3: 0.46306389 | FH3: 0.45535694 | FI3: 0.45059722 | FJ3: 0.46157083 | FK3: 0.50513194 | FL3: 0.58155278 | FM3: 0.60006944 | FN3: 0.60059167 | FO3: 0.56550417 | FP3: 0.37284583 | FQ3: 0.33070694 | FR3: 0.29192917 | FS3: 0.26893333 | FT3: 0.25480833 | FU3: 0.24577778 | FV3: 0.24432639 | FW3: 0.24483472 | FX3: 0.25624861 | FY3: 0.27996528 | FZ3: 0.3020375 | GA3: 0.31405 | GB3: 0.33623889 | GC3: 0.36834167 | GD3: 0.37083472 | GE3: 0.37256389 | GF3: 0.36315556 | GG3: 0.35775278 | GH3: 0.36501944 | GI3: 0.40037083 | GJ3: 0.46381111 | GK3: 0.47711944 | GL3: 0.46964028 | GM3: 0.42694861 | GN3: 0.31003056 | GO3: 0.26340833 | GP3: 0.22777778 | GQ3: 0.20798611 | GR3: 0.19797778 | GS3: 0.19301806 | GT3: 0.19810972 | GU3: 0.21740278 | GV3: 0.24953194 | GW3: 0.27817778 | GX3: 0.30193611 | GY3: 0.30790278 | GZ3: 0.32483472 | HA3: 0.3524625 | HB3: 0.34000278 | HC3: 0.33257361 | HD3: 0.31211528 | HE3: 0.29743056 | HF3: 0.30383611 | HG3: 0.35547639 | HH3: 0.45389861 | HI3: 0.46229306 | HJ3: 0.42898056 | HK3: 0.37086389 | HL3: 0.30047361 | HM3: 0.25137778 | HN3: 0.2117625 | HO3: 0.19076667 | HP3: 0.18014028 | HQ3: 0.17659306 | HR3: 0.18418472 | HS3: 0.21292778 | HT3: 0.26337361 | HU3: 0.29510139 | HV3: 0.31792083 | HW3: 0.319275 | HX3: 0.33444722 | HY3: 0.36123056 | HZ3: 0.34259167 | IA3: 0.32954444 | IB3: 0.30553889 | IC3: 0.29149306 | ID3: 0.31218056 | IE3: 0.3966375 | IF3: 0.50456667 | IG3: 0.47767083 | IH3: 0.43351944 | II3: 0.366375 | IJ3: 0.33417361 | IK3: 0.27396944 | IL3: 0.23087778 | IM3: 0.20703333 | IN3: 0.19650556 | IO3: 0.19418611 | IP3: 0.20834444 | IQ3: 0.25153056 | IR3: 0.31231944 | IS3: 0.34522778 | IT3: 0.36645417 | IU3: 0.36380139 | IV3: 0.37859722 | IW3: 0.40983472 | IX3: 0.39267639 | IY3: 0.38324583 | IZ3: 0.36567361 | JA3: 0.37589722 | JB3: 0.4369875 | JC3: 0.52210278 | JD3: 0.59027917 | JE3: 0.5520375 | JF3: 0.49856528 | JG3: 0.4144625 | JH3: 0.38474722 | JI3: 0.31668889 | JJ3: 0.26655278 | JK3: 0.237925 | JL3: 0.22480833 | JM3: 0.22219306 | JN3: 0.23841944 | JO3: 0.28364583 | JP3: 0.34744861 | JQ3: 0.39637778 | JR3: 0.43582083 | JS3: 0.44650694 | JT3: 0.4660125 | JU3: 0.49456389 | JV3: 0.47158194 | JW3: 0.46194722 | JX3: 0.44767361 | JY3: 0.45953194 | JZ3: 0.50940972 | KA3: 0.57381806 | KB3: 0.63438889 | KC3: 0.59826389 | KD3: 0.54655833 | KE3: 0.46618889
A4: SAB | B4: 0.41365417 | C4: 0.33746667 | D4: 0.28340833 | E4: 0.2551875 | F4: 0.24276667 | G4: 0.24102083 | H4: 0.25675 | I4: 0.29516667 | J4: 0.36200833 | K4: 0.43142083 | L4: 0.47593333 | M4: 0.47959583 | N4: 0.48820833 | O4: 0.52357083 | P4: 0.50879167 | Q4: 0.500875 | R4: 0.47058333 | S4: 0.47292917 | T4: 0.54340417 | U4: 0.644475 | V4: 0.72051667 | W4: 0.65069167 | X4: 0.58293333 | Y4: 0.49500833 | AA4: 0.38150417 | AB4: 0.30844167 | AC4: 0.25910833 | AD4: 0.23332917 | AE4: 0.22224167 | AF4: 0.2210125 | AG4: 0.23723333 | AH4: 0.2780875 | AI4: 0.3451125 | AJ4: 0.40710833 | AK4: 0.44250417 | AL4: 0.43632083 | AM4: 0.44362917 | AN4: 0.48131667 | AO4: 0.4658625 | AP4: 0.455875 | AQ4: 0.42030417 | AR4: 0.41020833 | AS4: 0.46112917 | AT4: 0.578875 | AU4: 0.66084167 | AV4: 0.59419167 | AW4: 0.5282625 | AX4: 0.451225 | AZ4: 0.3599375 | BA4: 0.2911875 | BB4: 0.2452875 | BC4: 0.22210833 | BD4: 0.2120625 | BE4: 0.21070833 | BF4: 0.22660417 | BG4: 0.26429167 | BH4: 0.32240417 | BI4: 0.38090833 | BJ4: 0.4104875 | BK4: 0.40285833 | BL4: 0.41194167 | BM4: 0.4513375 | BN4: 0.44100417 | BO4: 0.43021667 | BP4: 0.39350833 | BQ4: 0.37471667 | BR4: 0.40624167 | BS4: 0.51564583 | BT4: 0.62836667 | BU4: 0.56584167 | BV4: 0.5024875 | BW4: 0.42879167 | BX4: 0.345475 | BY4: 0.27394167 | BZ4: 0.228925 | CA4: 0.20603333 | CB4: 0.19554167 | CC4: 0.19270833 | CD4: 0.20213333 | CE4: 0.22796667 | CF4: 0.278175 | CG4: 0.33490833 | CH4: 0.36791667 | CI4: 0.36815 | CJ4: 0.38171667 | CK4: 0.42286667 | CL4: 0.41279167 | CM4: 0.40576667 | CN4: 0.373425 | CO4: 0.35244167 | CP4: 0.36039167 | CQ4: 0.42074167 | CR4: 0.52729167 | CS4: 0.52483333 | CT4: 0.48010833 | CU4: 0.4119 | CV4: 0.33242083 | CW4: 0.279475 | CX4: 0.23690833 | CY4: 0.21350833 | CZ4: 0.2021875 | DA4: 0.19669167 | DB4: 0.2011625 | DC4: 0.21475833 | DD4: 0.257125 | DE4: 0.3083375 | DF4: 0.334875 | DG4: 0.3316625 | DH4: 0.3433125 | DI4: 0.38229583 | DJ4: 0.38156667 | DK4: 0.3776125 | DL4: 0.35030417 | DM4: 0.3295875 | DN4: 0.32927917 | DO4: 0.36892083 | DP4: 0.44985 | DQ4: 0.4521 | DR4: 0.43530417 | DS4: 0.38802917 | DT4: 0.37652917 | DU4: 0.31949167 | DV4: 0.27449583 | DW4: 0.24924583 | DX4: 0.2351125 | DY4: 0.2266375 | DZ4: 0.22452083 | EA4: 0.22709583 | EB4: 0.25595833 | EC4: 0.29654583 | ED4: 0.3202125 | EE4: 0.32435 | EF4: 0.34122083 | EG4: 0.380925 | EH4: 0.38928333 | EI4: 0.3911625 | EJ4: 0.37236667 | EK4: 0.3578125 | EL4: 0.36061667 | EM4: 0.39242917 | EN4: 0.45640417 | EO4: 0.46138333 | EP4: 0.4529125 | EQ4: 0.42685 | ER4: 0.4643 | ES4: 0.40444167 | ET4: 0.35374167 | EU4: 0.32245833 | EV4: 0.3027 | EW4: 0.28854167 | EX4: 0.280425 | EY4: 0.27305833 | EZ4: 0.28835 | FA4: 0.3176 | FB4: 0.339525 | FC4: 0.351675 | FD4: 0.38111667 | FE4: 0.43538333 | FF4: 0.46204167 | FG4: 0.474 | FH4: 0.463075 | FI4: 0.45411667 | FJ4: 0.45726667 | FK4: 0.48915833 | FL4: 0.55203333 | FM4: 0.558325 | FN4: 0.54911667 | FO4: 0.51949167 | FP4: 0.36284167 | FQ4: 0.33672917 | FR4: 0.29712917 | FS4: 0.27343333 | FT4: 0.25889583 | FU4: 0.24932917 | FV4: 0.2471 | FW4: 0.24641667 | FX4: 0.2596875 | FY4: 0.2871625 | FZ4: 0.31025 | GA4: 0.32070417 | GB4: 0.34184167 | GC4: 0.38137083 | GD4: 0.392425 | GE4: 0.396375 | GF4: 0.38430417 | GG4: 0.3754875 | GH4: 0.377975 | GI4: 0.40603333 | GJ4: 0.46004583 | GK4: 0.46215417 | GL4: 0.4475125 | GM4: 0.4095625 | GN4: 0.30650417 | GO4: 0.265575 | GP4: 0.2306625 | GQ4: 0.21089167 | GR4: 0.20042083 | GS4: 0.19520417 | GT4: 0.19946667 | GU4: 0.21342083 | GV4: 0.24517083 | GW4: 0.28854167 | GX4: 0.31711667 | GY4: 0.32118333 | GZ4: 0.33663333 | HA4: 0.37486667 | HB4: 0.3690375 | HC4: 0.3623 | HD4: 0.33675 | HE4: 0.31914167 | HF4: 0.32225 | HG4: 0.36632917 | HH4: 0.44998333 | HI4: 0.44155833 | HJ4: 0.399925 | HK4: 0.35264167 | HL4: 0.30331667 | HM4: 0.25355833 | HN4: 0.21343333 | HO4: 0.19210833 | HP4: 0.18180833 | HQ4: 0.17804167 | HR4: 0.18491667 | HS4: 0.20715 | HT4: 0.256925 | HU4: 0.30718333 | HV4: 0.33426667 | HW4: 0.32954167 | HX4: 0.33914167 | HY4: 0.37645833 | HZ4: 0.36854167 | IA4: 0.3556 | IB4: 0.3251 | IC4: 0.30481667 | ID4: 0.32016667 | IE4: 0.39871667 | IF4: 0.50209167 | IG4: 0.46023333 | IH4: 0.40915833 | II4: 0.353925 | IJ4: 0.34012083 | IK4: 0.27542917 | IL4: 0.23154167 | IM4: 0.20785833 | IN4: 0.19709583 | IO4: 0.1945625 | IP4: 0.20795 | IQ4: 0.2433375 | IR4: 0.30735 | IS4: 0.36239583 | IT4: 0.386675 | IU4: 0.376125 | IV4: 0.38466667 | IW4: 0.42706667 | IX4: 0.421925 | IY4: 0.41624583 | IZ4: 0.3937625 | JA4: 0.39798333 | JB4: 0.45325833 | JC4: 0.52873333 | JD4: 0.58745 | JE4: 0.53030833 | JF4: 0.47059583 | JG4: 0.4021 | JH4: 0.392325 | JI4: 0.31664167 | JJ4: 0.266375 | JK4: 0.23793333 | JL4: 0.224775 | JM4: 0.22209167 | JN4: 0.23648333 | JO4: 0.27244167 | JP4: 0.33710833 | JQ4: 0.406325 | JR4: 0.45313333 | JS4: 0.4598 | JT4: 0.475575 | JU4: 0.51786667 | JV4: 0.51405833 | JW4: 0.51340833 | JX4: 0.49603333 | JY4: 0.50355 | JZ4: 0.54914167 | KA4: 0.60540833 | KB4: 0.64815833 | KC4: 0.58659167 | KD4: 0.5241 | KE4: 0.45684167
A5: DOM | B5: 0.39804167 | C5: 0.35380417 | D5: 0.29930417 | E5: 0.26567917 | F5: 0.24778333 | G5: 0.24088333 | H5: 0.25067083 | I5: 0.2743375 | J5: 0.31360417 | K5: 0.37985 | L5: 0.45489167 | M5: 0.5023125 | N5: 0.544975 | O5: 0.56614167 | P5: 0.50901667 | Q5: 0.4909625 | R5: 0.4645 | S5: 0.47070417 | T5: 0.53905833 | U5: 0.62409583 | V5: 0.68750417 | W5: 0.64717917 | X5: 0.59026667 | Y5: 0.49232917 | AA5: 0.36559583 | AB5: 0.32231667 | AC5: 0.2727375 | AD5: 0.24183333 | AE5: 0.2277375 | AF5: 0.22358333 | AG5: 0.2348 | AH5: 0.26173333 | AI5: 0.30660417 | AJ5: 0.3783 | AK5: 0.45018333 | AL5: 0.47899583 | AM5: 0.50450417 | AN5: 0.514775 | AO5: 0.45620417 | AP5: 0.43642917 | AQ5: 0.40421667 | AR5: 0.39885417 | AS5: 0.45062917 | AT5: 0.573525 | AU5: 0.65456667 | AV5: 0.6125875 | AW5: 0.55615417 | AX5: 0.46065417 | AZ5: 0.3508875 | BA5: 0.3025125 | BB5: 0.2556125 | BC5: 0.1755125 | BD5: 0.2186375 | BE5: 0.21328333 | BF5: 0.22211667 | BG5: 0.24338333 | BH5: 0.280875 | BI5: 0.34447917 | BJ5: 0.41012083 | BK5: 0.4367125 | BL5: 0.46570417 | BM5: 0.48261667 | BN5: 0.42982917 | BO5: 0.41133333 | BP5: 0.379575 | BQ5: 0.36347917 | BR5: 0.3947875 | BS5: 0.4994 | BT5: 0.61356667 | BU5: 0.589425 | BV5: 0.53799167 | BW5: 0.444825 | BX5: 0.3353875 | BY5: 0.2845375 | BZ5: 0.23685417 | CA5: 0.2116125 | CB5: 0.20011667 | CC5: 0.195775 | CD5: 0.2024125 | CE5: 0.21952083 | CF5: 0.25164167 | CG5: 0.3164 | CH5: 0.3804125 | CI5: 0.40665833 | CJ5: 0.4317625 | CK5: 0.4413625 | CL5: 0.3817375 | CM5: 0.36220417 | CN5: 0.33582083 | CO5: 0.3159125 | CP5: 0.3224625 | CQ5: 0.3803375 | CR5: 0.48617917 | CS5: 0.5198625 | CT5: 0.493 | CU5: 0.41607917 | CV5: 0.32549167 | CW5: 0.28213333 | CX5: 0.23895833 | CY5: 0.21366667 | CZ5: 0.20123333 | DA5: 0.19488333 | DB5: 0.19719167 | DC5: 0.20225833 | DD5: 0.22751667 | DE5: 0.2867 | DF5: 0.34358333 | DG5: 0.36785833 | DH5: 0.394525 | DI5: 0.414175 | DJ5: 0.370675 | DK5: 0.35843333 | DL5: 0.33351667 | DM5: 0.31330833 | DN5: 0.315475 | DO5: 0.36083333 | DP5: 0.44635833 | DQ5: 0.46851667 | DR5: 0.46486667 | DS5: 0.40163333 | DT5: 0.39336667 | DU5: 0.318025 | DV5: 0.27640833 | DW5: 0.25 | DX5: 0.235125 | DY5: 0.22626667 | DZ5: 0.22328333 | EA5: 0.22219167 | EB5: 0.23943333 | EC5: 0.284 | ED5: 0.32565 | EE5: 0.34714167 | EF5: 0.373725 | EG5: 0.400725 | EH5: 0.38593333 | EI5: 0.38551667 | EJ5: 0.37211667 | EK5: 0.36165 | EL5: 0.36699167 | EM5: 0.40304167 | EN5: 0.47211667 | EO5: 0.48896667 | EP5: 0.49395833 | EQ5: 0.4621 | ER5: 0.51581667 | ES5: 0.41271667 | ET5: 0.36531667 | EU5: 0.33311667 | EV5: 0.31180833 | EW5: 0.29695 | EX5: 0.28791667 | EY5: 0.277575 | EZ5: 0.28129167 | FA5: 0.31160833 | FB5: 0.34924167 | FC5: 0.378825 | FD5: 0.418725 | FE5: 0.461575 | FF5: 0.468 | FG5: 0.48070833 | FH5: 0.47510833 | FI5: 0.46928333 | FJ5: 0.47886667 | FK5: 0.51709167 | FL5: 0.58793333 | FM5: 0.61089167 | FN5: 0.61969167 | FO5: 0.59029167 | FP5: 0.356325 | FQ5: 0.31613333 | FR5: 0.28105 | FS5: 0.2592 | FT5: 0.24564167 | FU5: 0.23744167 | FV5: 0.23643333 | FW5: 0.235175 | FX5: 0.24070833 | FY5: 0.26976667 | FZ5: 0.30260833 | GA5: 0.323375 | GB5: 0.347975 | GC5: 0.36753333 | GD5: 0.35274167 | GE5: 0.35290833 | GF5: 0.34608333 | GG5: 0.341375 | GH5: 0.34821667 | GI5: 0.37949167 | GJ5: 0.43449167 | GK5: 0.44954167 | GL5: 0.444175 | GM5: 0.40421667 | GN5: 0.30815833 | GO5: 0.26697083 | GP5: 0.23135833 | GQ5: 0.209625 | GR5: 0.1985375 | GS5: 0.19240417 | GT5: 0.19515833 | GU5: 0.20348333 | GV5: 0.222425 | GW5: 0.27003333 | GX5: 0.3189375 | GY5: 0.33988333 | GZ5: 0.3642125 | HA5: 0.38288333 | HB5: 0.3490125 | HC5: 0.33832917 | HD5: 0.31685833 | HE5: 0.29887917 | HF5: 0.30212917 | HG5: 0.34835 | HH5: 0.4418 | HI5: 0.45864167 | HJ5: 0.42867083 | HK5: 0.37041667 | HL5: 0.29413333 | HM5: 0.260125 | HN5: 0.2193 | HO5: 0.19565 | HP5: 0.18206667 | HQ5: 0.1774 | HR5: 0.18173333 | HS5: 0.1948 | HT5: 0.2287 | HU5: 0.28994167 | HV5: 0.34639167 | HW5: 0.3684 | HX5: 0.39653333 | HY5: 0.41621667 | HZ5: 0.36960833 | IA5: 0.35115833 | IB5: 0.32451667 | IC5: 0.31045833 | ID5: 0.33254167 | IE5: 0.41071667 | IF5: 0.50306667 | IG5: 0.47830833 | IH5: 0.43331667 | II5: 0.36338333 | IJ5: 0.32158333 | IK5: 0.28199167 | IL5: 0.238575 | IM5: 0.211 | IN5: 0.19824167 | IO5: 0.193875 | IP5: 0.201875 | IQ5: 0.222075 | IR5: 0.2634 | IS5: 0.33023333 | IT5: 0.389575 | IU5: 0.40901667 | IV5: 0.434075 | IW5: 0.45653333 | IX5: 0.41015833 | IY5: 0.39369167 | IZ5: 0.37154167 | JA5: 0.38140833 | JB5: 0.44299167 | JC5: 0.52436667 | JD5: 0.582725 | JE5: 0.54686667 | JF5: 0.49295833 | JG5: 0.40546667 | JH5: 0.37598333 | JI5: 0.32895417 | JJ5: 0.27732083 | JK5: 0.24422917 | JL5: 0.2277875 | JM5: 0.22229583 | JN5: 0.23323333 | JO5: 0.26000417 | JP5: 0.3040125 | JQ5: 0.382825 | JR5: 0.46505833 | JS5: 0.5070375 | JT5: 0.53960833 | JU5: 0.55044167 | JV5: 0.48544583 | JW5: 0.46330833 | JX5: 0.44827917 | JY5: 0.4602 | JZ5: 0.5039375 | KA5: 0.55694583 | KB5: 0.61262917 | KC5: 0.58797917 | KD5: 0.54087083 | KE5: 0.45985417
A6: Giorno_feriale | B6: 0.40644167 | C6: 0.31760417 | D6: 0.26710833 | E6: 0.2443 | F6: 0.23559167 | G6: 0.23711667 | H6: 0.26020417 | I6: 0.33162917 | J6: 0.42432917 | K6: 0.4315625 | L6: 0.42463333 | M6: 0.40825 | N6: 0.4158 | O6: 0.4453375 | P6: 0.43915 | Q6: 0.42997917 | R6: 0.41180833 | S6: 0.42647917 | T6: 0.50289167 | U6: 0.61682083 | V6: 0.707875 | W6: 0.67694583 | X6: 0.62744167 | Y6: 0.51654583 | AA6: 0.37700833 | AB6: 0.29542083 | AC6: 0.24838333 | AD6: 0.22717917 | AE6: 0.2189875 | AF6: 0.22082083 | AG6: 0.245025 | AH6: 0.32545833 | AI6: 0.41437083 | AJ6: 0.39223333 | AK6: 0.37043333 | AL6: 0.34758333 | AM6: 0.35385 | AN6: 0.37789167 | AO6: 0.37515 | AP6: 0.3653875 | AQ6: 0.34750833 | AR6: 0.34998333 | AS6: 0.41115 | AT6: 0.55051667 | AU6: 0.6594625 | AV6: 0.6340125 | AW6: 0.58686667 | AX6: 0.48140417 | AZ6: 0.35857917 | BA6: 0.281425 | BB6: 0.23655833 | BC6: 0.21642083 | BD6: 0.20868333 | BE6: 0.20973333 | BF6: 0.23265 | BG6: 0.3057 | BH6: 0.3782875 | BI6: 0.35695833 | BJ6: 0.3372625 | BK6: 0.31787917 | BL6: 0.326 | BM6: 0.35063333 | BN6: 0.34865417 | BO6: 0.33871667 | BP6: 0.31945417 | BQ6: 0.31493333 | BR6: 0.35564583 | BS6: 0.47872917 | BT6: 0.6188875 | BU6: 0.60598333 | BV6: 0.56229167 | BW6: 0.46043333 | BX6: 0.34136667 | BY6: 0.26502083 | BZ6: 0.22117083 | CA6: 0.20115833 | CB6: 0.19315833 | CC6: 0.1926 | CD6: 0.2094625 | CE6: 0.26882083 | CF6: 0.3361875 | CG6: 0.32624583 | CH6: 0.31111667 | CI6: 0.29317917 | CJ6: 0.2998 | CK6: 0.32614583 | CL6: 0.3251375 | CM6: 0.31500833 | CN6: 0.29345417 | CO6: 0.27988333 | CP6: 0.29567917 | CQ6: 0.37105417 | CR6: 0.50794167 | CS6: 0.54850417 | CT6: 0.52720417 | CU6: 0.43822083 | CV6: 0.332625 | CW6: 0.26049583 | CX6: 0.21935833 | CY6: 0.20010833 | CZ6: 0.191625 | DA6: 0.18875 | DB6: 0.198375 | DC6: 0.23364583 | DD6: 0.28828333 | DE6: 0.2875875 | DF6: 0.27905833 | DG6: 0.2682375 | DH6: 0.277975 | DI6: 0.30207917 | DJ6: 0.30442917 | DK6: 0.30017917 | DL6: 0.28541667 | DM6: 0.27495833 | DN6: 0.28699167 | DO6: 0.34622917 | DP6: 0.45489167 | DQ6: 0.48416667 | DR6: 0.48857917 | DS6: 0.42020833 | DT6: 0.40619583 | DU6: 0.33142083 | DV6: 0.28327083 | DW6: 0.258075 | DX6: 0.24435 | DY6: 0.2360375 | DZ6: 0.2351 | EA6: 0.24655833 | EB6: 0.28032083 | EC6: 0.29105833 | ED6: 0.2913625 | EE6: 0.29050833 | EF6: 0.3078375 | EG6: 0.34226667 | EH6: 0.3534375 | EI6: 0.3524625 | EJ6: 0.34044583 | EK6: 0.33612083 | EL6: 0.35131667 | EM6: 0.405075 | EN6: 0.49707083 | EO6: 0.52234583 | EP6: 0.52986667 | EQ6: 0.4876125 | ER6: 0.4976875 | ES6: 0.42378333 | ET6: 0.36670417 | EU6: 0.33477917 | EV6: 0.314525 | EW6: 0.29955417 | EX6: 0.29102917 | EY6: 0.28652083 | EZ6: 0.3013 | FA6: 0.30917083 | FB6: 0.31492917 | FC6: 0.32243333 | FD6: 0.35025417 | FE6: 0.39966667 | FF6: 0.42719583 | FG6: 0.43448333 | FH6: 0.4278875 | FI6: 0.42839167 | FJ6: 0.44857917 | FK6: 0.50914583 | FL6: 0.60469167 | FM6: 0.63099167 | FN6: 0.63296667 | FO6: 0.58672917 | FP6: 0.39937083 | FQ6: 0.33925833 | FR6: 0.29760833 | FS6: 0.27416667 | FT6: 0.2598875 | FU6: 0.2505625 | FV6: 0.24944583 | FW6: 0.2529125 | FX6: 0.26835 | FY6: 0.28296667 | FZ6: 0.29325417 | GA6: 0.29807083 | GB6: 0.3189 | GC6: 0.35612083 | GD6: 0.3673375 | GE6: 0.36840833 | GF6: 0.35907917 | GG6: 0.35639583 | GH6: 0.36886667 | GI6: 0.4155875 | GJ6: 0.49689583 | GK6: 0.5196625 | GL6: 0.51723333 | GM6: 0.46706667 | GN6: 0.31542917 | GO6: 0.25767917 | GP6: 0.2213125 | GQ6: 0.20344167 | GR6: 0.194975 | GS6: 0.19144583 | GT6: 0.19970417 | GU6: 0.23530417 | GV6: 0.281 | GW6: 0.27595833 | GX6: 0.26975417 | GY6: 0.26264167 | GZ6: 0.27365833 | HA6: 0.2996375 | HB6: 0.30195833 | HC6: 0.29709167 | HD6: 0.2827375 | HE6: 0.27427083 | HF6: 0.28712917 | HG6: 0.35175 | HH6: 0.4699125 | HI6: 0.48667917 | HJ6: 0.45834583 | HK6: 0.38953333 | HL6: 0.30397083 | HM6: 0.24045 | HN6: 0.20255417 | HO6: 0.18454167 | HP6: 0.17654583 | HQ6: 0.1743375 | HR6: 0.18590417 | HS6: 0.23683333 | HT6: 0.30449583 | HU6: 0.28817917 | HV6: 0.27310417 | HW6: 0.25988333 | HX6: 0.26766667 | HY6: 0.29101667 | HZ6: 0.289625 | IA6: 0.281875 | IB6: 0.267 | IC6: 0.25920417 | ID6: 0.28383333 | IE6: 0.38047917 | IF6: 0.50854167 | IG6: 0.49447083 | IH6: 0.45808333 | II6: 0.38181667 | IJ6: 0.34081667 | IK6: 0.2644875 | IL6: 0.22251667 | IM6: 0.20224167 | IN6: 0.19417917 | IO6: 0.19412083 | IP6: 0.21520833 | IQ6: 0.28917917 | IR6: 0.36620833 | IS6: 0.34305417 | IT6: 0.3231125 | IU6: 0.3062625 | IV6: 0.31705 | IW6: 0.34590417 | IX6: 0.34594583 | IY6: 0.3398 | IZ6: 0.33171667 | JA6: 0.3483 | JB6: 0.4147125 | JC6: 0.51320833 | JD6: 0.6006625 | JE6: 0.5789375 | JF6: 0.53214167 | JG6: 0.43582083 | JH6: 0.38593333 | JI6: 0.30447083 | JJ6: 0.2559625 | JK6: 0.2316125 | JL6: 0.2218625 | JM6: 0.22219167 | JN6: 0.24554167 | JO6: 0.31849167 | JP6: 0.401225 | JQ6: 0.39998333 | JR6: 0.38927083 | JS6: 0.37268333 | JT6: 0.38285417 | JU6: 0.41538333 | JV6: 0.41524167 | JW6: 0.409125 | JX6: 0.39870833 | JY6: 0.41484583 | JZ6: 0.47515 | KA6: 0.5591 | KB6: 0.64237917 | KC6: 0.62022083 | KD6: 0.57470417 | KE6: 0.48187083
A7: 2 | B7: 0.44666508 | C7: 0.37639683 | D7: 0.3245746 | E7: 0.29536508 | F7: 0.28248889 | G7: 0.27978571 | H7: 0.29772063 | I7: 0.34855079 | J7: 0.41732381 | K7: 0.45194444 | L7: 0.47764921 | M7: 0.4827381 | N7: 0.48835238 | O7: 0.50667778 | P7: 0.49270317 | Q7: 0.49101111 | R7: 0.48632063 | S7: 0.51934762 | T7: 0.6034254 | U7: 0.68756984 | V7: 0.74014603 | W7: 0.68981429 | X7: 0.63084762 | Y7: 0.53838413 | AA7: 0.40742698 | AB7: 0.34180317 | AC7: 0.29374127 | AD7: 0.26854921 | AE7: 0.25717619 | AF7: 0.25663651 | AG7: 0.27643333 | AH7: 0.33065079 | AI7: 0.39220794 | AJ7: 0.41493333 | AK7: 0.42962698 | AL7: 0.42451905 | AM7: 0.42775556 | AN7: 0.44940159 | AO7: 0.43038571 | AP7: 0.42674921 | AQ7: 0.41263016 | AR7: 0.42662698 | AS7: 0.5036619 | AT7: 0.61625238 | AU7: 0.6801619 | AV7: 0.63548413 | AW7: 0.57941905 | AX7: 0.49465397 | AZ7: 0.37646508 | BA7: 0.31545079 | BB7: 0.2718619 | BC7: 0.23108254 | BD7: 0.24153492 | BE7: 0.24023968 | BF7: 0.25711587 | BG7: 0.30385714 | BH7: 0.35067302 | BI7: 0.37518254 | BJ7: 0.3893 | BK7: 0.38236032 | BL7: 0.38705873 | BM7: 0.40515873 | BN7: 0.39013333 | BO7: 0.38492222 | BP7: 0.36743651 | BQ7: 0.3641873 | BR7: 0.41196032 | BS7: 0.53337302 | BT7: 0.63665079 | BU7: 0.60142381 | BV7: 0.54795714 | BW7: 0.46229365 | BX7: 0.35765873 | BY7: 0.2937254 | BZ7: 0.24873333 | CA7: 0.22622857 | CB7: 0.21657937 | CC7: 0.21454603 | CD7: 0.22598254 | CE7: 0.2630873 | CF7: 0.31075873 | CG7: 0.33988095 | CH7: 0.35985397 | CI7: 0.35620794 | CJ7: 0.36281587 | CK7: 0.38100317 | CL7: 0.36581429 | CM7: 0.36030635 | CN7: 0.34254127 | CO7: 0.32927143 | CP7: 0.34515397 | CQ7: 0.41253016 | CR7: 0.52580952 | CS7: 0.55076825 | CT7: 0.51406667 | CU7: 0.43808571 | CV7: 0.3383873 | CW7: 0.2835 | CX7: 0.24253968 | CY7: 0.22082063 | CZ7: 0.21050635 | DA7: 0.20639683 | DB7: 0.21134603 | DC7: 0.22860952 | DD7: 0.26718413 | DE7: 0.29686984 | DF7: 0.31421587 | DG7: 0.31406984 | DH7: 0.32351429 | DI7: 0.34612381 | DJ7: 0.33831746 | DK7: 0.33446667 | DL7: 0.32086508 | DM7: 0.30879683 | DN7: 0.31722698 | DO7: 0.36277778 | DP7: 0.44707143 | DQ7: 0.47318095 | DR7: 0.46672857 | DS7: 0.40870952 | DT7: 0.42152857 | DU7: 0.35031587 | DV7: 0.30596825 | DW7: 0.2799127 | DX7: 0.26455079 | DY7: 0.25525238 | DZ7: 0.24997143 | EA7: 0.24954286 | EB7: 0.27271111 | EC7: 0.2949619 | ED7: 0.30843492 | EE7: 0.31445079 | EF7: 0.33370159 | EG7: 0.36748571 | EH7: 0.37741587 | EI7: 0.37794762 | EJ7: 0.36701587 | EK7: 0.36236984 | EL7: 0.37270317 | EM7: 0.41370476 | EN7: 0.48515397 | EO7: 0.51121746 | EP7: 0.51889048 | EQ7: 0.48592857 | ER7: 0.54173333 | ES7: 0.46277619 | ET7: 0.41044286 | EU7: 0.37698254 | EV7: 0.35420952 | EW7: 0.33696032 | EX7: 0.32380317 | EY7: 0.30748889 | EZ7: 0.31067937 | FA7: 0.32190317 | FB7: 0.33669365 | FC7: 0.35420794 | FD7: 0.39028889 | FE7: 0.44528254 | FF7: 0.47497937 | FG7: 0.48489048 | FH7: 0.47885397 | FI7: 0.47801429 | FJ7: 0.49227143 | FK7: 0.53634921 | FL7: 0.6105746 | FM7: 0.6400746 | FN7: 0.64743016 | FO7: 0.6129 | FP7: 0.40993016 | FQ7: 0.36926667 | FR7: 0.32945079 | FS7: 0.30436349 | FT7: 0.28872381 | FU7: 0.27767619 | FV7: 0.27403651 | FW7: 0.27023492 | FX7: 0.27422222 | FY7: 0.29007619 | FZ7: 0.30486349 | GA7: 0.31496984 | GB7: 0.33822063 | GC7: 0.37394286 | GD7: 0.38442222 | GE7: 0.38508413 | GF7: 0.37514921 | GG7: 0.37171746 | GH7: 0.38102063 | GI7: 0.4191 | GJ7: 0.48564603 | GK7: 0.50965714 | GL7: 0.50381746 | GM7: 0.46378095 | GN7: 0.31757302 | GO7: 0.27186984 | GP7: 0.23740317 | GQ7: 0.21866349 | GR7: 0.20869206 | GS7: 0.2042381 | GT7: 0.20966032 | GU7: 0.23192857 | GV7: 0.26113333 | GW7: 0.28256508 | GX7: 0.29993492 | GY7: 0.30109524 | GZ7: 0.31137143 | HA7: 0.33172222 | HB7: 0.32388571 | HC7: 0.3184873 | HD7: 0.30447937 | HE7: 0.29616984 | HF7: 0.30766825 | HG7: 0.3622746 | HH7: 0.45756349 | HI7: 0.46273492 | HJ7: 0.42897619 | HK7: 0.37515079 | HL7: 0.30156349 | HM7: 0.25535397 | HN7: 0.21783333 | HO7: 0.19815714 | HP7: 0.18845873 | HQ7: 0.18533175 | HR7: 0.19352063 | HS7: 0.22720159 | HT7: 0.27772857 | HU7: 0.29942381 | HV7: 0.31159365 | HW7: 0.30549524 | HX7: 0.31046032 | HY7: 0.32879683 | HZ7: 0.31767143 | IA7: 0.31087619 | IB7: 0.29611905 | IC7: 0.28956032 | ID7: 0.31698413 | IE7: 0.40475397 | IF7: 0.49304762 | IG7: 0.46627619 | IH7: 0.4244 | II7: 0.36276984 | IJ7: 0.34689206 | IK7: 0.28773016 | IL7: 0.24536667 | IM7: 0.22277778 | IN7: 0.2126127 | IO7: 0.21069206 | IP7: 0.22555714 | IQ7: 0.27336508 | IR7: 0.33251587 | IS7: 0.35847619 | IT7: 0.37261429 | IU7: 0.36623175 | IV7: 0.37471111 | IW7: 0.39902857 | IX7: 0.39125714 | IY7: 0.39193175 | IZ7: 0.38930476 | JA7: 0.4155127 | JB7: 0.47646984 | JC7: 0.54220476 | JD7: 0.59257778 | JE7: 0.55667143 | JF7: 0.50275556 | JG7: 0.42413492 | JH7: 0.40093175 | JI7: 0.33541587 | JJ7: 0.28705556 | JK7: 0.25974444 | JL7: 0.24719524 | JM7: 0.24495397 | JN7: 0.26173651 | JO7: 0.3112254 | JP7: 0.3776746 | JQ7: 0.42392698 | JR7: 0.45628889 | JS7: 0.46230952 | JT7: 0.47570476 | JU7: 0.49794286 | JV7: 0.4830619 | JW7: 0.48401429 | JX7: 0.48441429 | JY7: 0.50712381 | JZ7: 0.55307302 | KA7: 0.6030127 | KB7: 0.64711905 | KC7: 0.61086032 | KD7: 0.55710952 | KE7: 0.47982222
A8: SAB | B8: 0.45411905 | C8: 0.37398571 | D8: 0.32039524 | E8: 0.29139048 | F8: 0.28047143 | G8: 0.28051905 | H8: 0.29985238 | I8: 0.34552857 | J8: 0.42093333 | K8: 0.46575238 | L8: 0.48740476 | M8: 0.47794286 | N8: 0.46962857 | O8: 0.49 | P8: 0.492 | Q8: 0.49577143 | R8: 0.48961905 | S8: 0.52346667 | T8: 0.61459048 | U8: 0.69478095 | V8: 0.74383333 | W8: 0.67799048 | X8: 0.61549524 | Y8: 0.53497619 | AA8: 0.4138619 | AB8: 0.33722381 | AC8: 0.28871429 | AD8: 0.26475238 | AE8: 0.25415238 | AF8: 0.25535238 | AG8: 0.2743619 | AH8: 0.32339524 | AI8: 0.38869524 | AJ8: 0.43183333 | AK8: 0.44615714 | AL8: 0.43970476 | AM8: 0.43758571 | AN8: 0.4633381 | AO8: 0.4623 | AP8: 0.46619524 | AQ8: 0.4462381 | AR8: 0.45454286 | AS8: 0.5326619 | AT8: 0.6237381 | AU8: 0.67470476 | AV8: 0.6143619 | AW8: 0.55511905 | AX8: 0.48393333 | AZ8: 0.38406667 | BA8: 0.31558095 | BB8: 0.27271429 | BC8: 0.25070952 | BD8: 0.24158571 | BE8: 0.24074762 | BF8: 0.25758571 | BG8: 0.29907619 | BH8: 0.34991905 | BI8: 0.39457143 | BJ8: 0.40739524 | BK8: 0.39082381 | BL8: 0.38953333 | BM8: 0.41850952 | BN8: 0.41479048 | BO8: 0.41504762 | BP8: 0.3957 | BQ8: 0.38905714 | BR8: 0.4358619 | BS8: 0.55421429 | BT8: 0.6401 | BU8: 0.57945714 | BV8: 0.51934286 | BW8: 0.44957143 | BX8: 0.36408571 | BY8: 0.29312381 | BZ8: 0.24891429 | CA8: 0.22574286 | CB8: 0.2156381 | CC8: 0.21317143 | CD8: 0.22280952 | CE8: 0.25235238 | CF8: 0.30311429 | CG8: 0.35057143 | CH8: 0.3733619 | CI8: 0.3639619 | CJ8: 0.36524762 | CK8: 0.39451429 | CL8: 0.39839048 | CM8: 0.40247619 | CN8: 0.38424762 | CO8: 0.36973333 | CP8: 0.3835619 | CQ8: 0.44492381 | CR8: 0.54054286 | CS8: 0.54122857 | CT8: 0.49507619 | CU8: 0.4294 | CV8: 0.33862381 | CW8: 0.2884 | CX8: 0.24782857 | CY8: 0.22545238 | CZ8: 0.21473333 | DA8: 0.21009524 | DB8: 0.21399048 | DC8: 0.22809524 | DD8: 0.27142381 | DE8: 0.31306667 | DF8: 0.3309381 | DG8: 0.32552381 | DH8: 0.33218095 | DI8: 0.36252857 | DJ8: 0.36659048 | DK8: 0.36560476 | DL8: 0.34791905 | DM8: 0.33170476 | DN8: 0.33549524 | DO8: 0.37248095 | DP8: 0.44481429 | DQ8: 0.45424286 | DR8: 0.43628095 | DS8: 0.3899 | DT8: 0.40242381 | DU8: 0.34447143 | DV8: 0.30151429 | DW8: 0.27590476 | DX8: 0.26071429 | DY8: 0.25163333 | DZ8: 0.24615714 | EA8: 0.24452381 | EB8: 0.27104286 | EC8: 0.30175238 | ED8: 0.31591905 | EE8: 0.31728095 | EF8: 0.33194286 | EG8: 0.36937143 | EH8: 0.38462381 | EI8: 0.38808571 | EJ8: 0.37502857 | EK8: 0.36578095 | EL8: 0.37016667 | EM8: 0.4019 | EN8: 0.46124762 | EO8: 0.47764286 | EP8: 0.47757143 | EQ8: 0.45054762 | ER8: 0.51802857 | ES8: 0.45399048 | ET8: 0.40214286 | EU8: 0.36927619 | EV8: 0.34728571 | EW8: 0.33057143 | EX8: 0.31806667 | EY8: 0.30205714 | EZ8: 0.309 | FA8: 0.32629524 | FB8: 0.34309524 | FC8: 0.35815238 | FD8: 0.39301905 | FE8: 0.4530381 | FF8: 0.48873333 | FG8: 0.50110476 | FH8: 0.49274286 | FI8: 0.48898095 | FJ8: 0.49621905 | FK8: 0.52891429 | FL8: 0.58635238 | FM8: 0.60395238 | FN8: 0.60162857 | FO8: 0.57245714 | FP8: 0.39355714 | FQ8: 0.37965238 | FR8: 0.33830476 | FS8: 0.31227619 | FT8: 0.29579524 | FU8: 0.28389524 | FV8: 0.27936667 | FW8: 0.2734619 | FX8: 0.27823333 | FY8: 0.29936667 | FZ8: 0.31662381 | GA8: 0.32898095 | GB8: 0.35411905 | GC8: 0.39972381 | GD8: 0.4208619 | GE8: 0.42252381 | GF8: 0.40740476 | GG8: 0.39668095 | GH8: 0.39819048 | GI8: 0.42299524 | GJ8: 0.47290952 | GK8: 0.48522857 | GL8: 0.4725 | GM8: 0.43683333 | GN8: 0.31548571 | GO8: 0.27251905 | GP8: 0.23890952 | GQ8: 0.22059048 | GR8: 0.21060952 | GS8: 0.20613333 | GT8: 0.2108381 | GU8: 0.22790952 | GV8: 0.259 | GW8: 0.2955381 | GX8: 0.31899524 | GY8: 0.31837143 | GZ8: 0.3271 | HA8: 0.35338571 | HB8: 0.35138095 | HC8: 0.34586667 | HD8: 0.32930952 | HE8: 0.3178 | HF8: 0.32424762 | HG8: 0.36940476 | HH8: 0.44921429 | HI8: 0.4417619 | HJ8: 0.40196667 | HK8: 0.35939524 | HL8: 0.30666667 | HM8: 0.25650476 | HN8: 0.2192 | HO8: 0.1994381 | HP8: 0.19041905 | HQ8: 0.18695238 | HR8: 0.1944381 | HS8: 0.22337143 | HT8: 0.27729524 | HU8: 0.31606667 | HV8: 0.3308381 | HW8: 0.32105714 | HX8: 0.3224 | HY8: 0.34989524 | HZ8: 0.34732381 | IA8: 0.34274286 | IB8: 0.32413333 | IC8: 0.309 | ID8: 0.32759048 | IE8: 0.40941905 | IF8: 0.48830476 | IG8: 0.44977143 | IH8: 0.40374286 | II8: 0.3532 | IJ8: 0.35667619 | IK8: 0.28975238 | IL8: 0.24602857 | IM8: 0.22365238 | IN8: 0.21350952 | IO8: 0.21142857 | IP8: 0.22556667 | IQ8: 0.2675 | IR8: 0.33281905 | IS8: 0.37909524 | IT8: 0.39767143 | IU8: 0.38651429 | IV8: 0.3917619 | IW8: 0.42789048 | IX8: 0.43054762 | IY8: 0.43503333 | IZ8: 0.42887619 | JA8: 0.4479 | JB8: 0.50149524 | JC8: 0.55415238 | JD8: 0.5902 | JE8: 0.53913333 | JF8: 0.48040952 | JG8: 0.4166381 | JH8: 0.40904762 | JI8: 0.33531429 | JJ8: 0.28701905 | JK8: 0.25914286 | JL8: 0.24655238 | JM8: 0.2438381 | JN8: 0.2585619 | JO8: 0.2996 | JP8: 0.36839048 | JQ8: 0.43626667 | JR8: 0.47525714 | JS8: 0.47685714 | JT8: 0.48671429 | JU8: 0.51935238 | JV8: 0.52382857 | JW8: 0.53352381 | JX8: 0.53155238 | JY8: 0.55125714 | JZ8: 0.59410476 | KA8: 0.63468571 | KB8: 0.66007619 | KC8: 0.60042857 | KD8: 0.53598095 | KE8: 0.47122857
A9: DOM | B9: 0.44172857 | C9: 0.39694762 | D9: 0.3446619 | E9: 0.30948095 | F9: 0.28964286 | G9: 0.28105714 | H9: 0.29041905 | I9: 0.3173 | J9: 0.3616381 | K9: 0.42552857 | L9: 0.49844762 | M9: 0.54248095 | N9: 0.56921429 | O9: 0.58275238 | P9: 0.5338381 | Q9: 0.52357143 | R9: 0.51781429 | S9: 0.54692857 | T9: 0.62274286 | U9: 0.69696667 | V9: 0.73458095 | W9: 0.6829 | X9: 0.62539048 | Y9: 0.53032381 | AA9: 0.39983333 | AB9: 0.35691429 | AC9: 0.30877619 | AD9: 0.27855714 | AE9: 0.26238571 | AF9: 0.25815238 | AG9: 0.2686381 | AH9: 0.29470476 | AI9: 0.34015714 | AJ9: 0.40220952 | AK9: 0.46265238 | AL9: 0.48207619 | AM9: 0.49612857 | AN9: 0.51784762 | AO9: 0.45554286 | AP9: 0.44014762 | AQ9: 0.4241 | AR9: 0.43555714 | AS9: 0.50603333 | AT9: 0.62177143 | AU9: 0.67214762 | AV9: 0.63239524 | AW9: 0.57520476 | AX9: 0.48916667 | AZ9: 0.36725238 | BA9: 0.32676667 | BB9: 0.28152381 | BC9: 0.19984286 | BD9: 0.24751905 | BE9: 0.24279524 | BF9: 0.2528 | BG9: 0.2737619 | BH9: 0.3043 | BI9: 0.36618095 | BJ9: 0.42165714 | BK9: 0.4398619 | BL9: 0.4536381 | BM9: 0.45892381 | BN9: 0.41336667 | BO9: 0.39971905 | BP9: 0.37871905 | BQ9: 0.37423333 | BR9: 0.41864762 | BS9: 0.53205238 | BT9: 0.63089524 | BU9: 0.60460476 | BV9: 0.54970476 | BW9: 0.46035714 | BX9: 0.35093333 | BY9: 0.30422381 | BZ9: 0.25664762 | CA9: 0.23168095 | CB9: 0.22048095 | CC9: 0.21684286 | CD9: 0.22379524 | CE9: 0.2405619 | CF9: 0.27252381 | CG9: 0.33363333 | CH9: 0.39121905 | CI9: 0.40987619 | CJ9: 0.42563333 | CK9: 0.42904762 | CL9: 0.37518095 | CM9: 0.35874286 | CN9: 0.3412381 | CO9: 0.32731429 | CP9: 0.3411381 | CQ9: 0.4017 | CR9: 0.5067619 | CS9: 0.54040476 | CT9: 0.50617619 | CU9: 0.43149048 | CV9: 0.33447619 | CW9: 0.28974286 | CX9: 0.24746667 | CY9: 0.22339048 | CZ9: 0.21148571 | DA9: 0.20629524 | DB9: 0.20794286 | DC9: 0.21040952 | DD9: 0.23615238 | DE9: 0.29293333 | DF9: 0.34093333 | DG9: 0.35873333 | DH9: 0.37368571 | DI9: 0.38994286 | DJ9: 0.35539048 | DK9: 0.34485714 | DL9: 0.33225714 | DM9: 0.31974286 | DN9: 0.32874286 | DO9: 0.37132381 | DP9: 0.44679048 | DQ9: 0.47530476 | DR9: 0.47073333 | DS9: 0.40924762 | DT9: 0.41977143 | DU9: 0.3407619 | DV9: 0.29917143 | DW9: 0.27297143 | DX9: 0.25773333 | DY9: 0.24859048 | DZ9: 0.24257143 | EA9: 0.2366381 | EB9: 0.2536381 | EC9: 0.28906667 | ED9: 0.3203619 | EE9: 0.33740952 | EF9: 0.3604381 | EG9: 0.38669524 | EH9: 0.3810381 | EI9: 0.37804762 | EJ9: 0.36784762 | EK9: 0.36402857 | EL9: 0.37426667 | EM9: 0.41145714 | EN9: 0.47607619 | EO9: 0.50349524 | EP9: 0.51519048 | EQ9: 0.48555238 | ER9: 0.56661905 | ES9: 0.46286667 | ET9: 0.4144 | EU9: 0.38086667 | EV9: 0.35766667 | EW9: 0.34059048 | EX9: 0.32693333 | EY9: 0.30745714 | EZ9: 0.30519048 | FA9: 0.32621905 | FB9: 0.35448571 | FC9: 0.38250476 | FD9: 0.42260952 | FE9: 0.47093333 | FF9: 0.4874381 | FG9: 0.49768571 | FH9: 0.49386667 | FI9: 0.4938381 | FJ9: 0.50886667 | FK9: 0.54984762 | FL9: 0.61857143 | FM9: 0.6528 | FN9: 0.66892381 | FO9: 0.63993333 | FP9: 0.3944381 | FQ9: 0.34611429 | FR9: 0.31160952 | FS9: 0.28852381 | FT9: 0.27468571 | FU9: 0.26532381 | FV9: 0.26281905 | FW9: 0.25724762 | FX9: 0.25666667 | FY9: 0.28074286 | FZ9: 0.3067619 | GA9: 0.3218381 | GB9: 0.3436 | GC9: 0.36385714 | GD9: 0.35491429 | GE9: 0.35380952 | GF9: 0.3485619 | GG9: 0.34934286 | GH9: 0.35989524 | GI9: 0.39610476 | GJ9: 0.4556381 | GK9: 0.48093333 | GL9: 0.47915238 | GM9: 0.44413333 | GN9: 0.31439524 | GO9: 0.27487143 | GP9: 0.24019048 | GQ9: 0.21975238 | GR9: 0.20836667 | GS9: 0.20275714 | GT9: 0.20575714 | GU9: 0.21516667 | GV9: 0.23402381 | GW9: 0.27689048 | GX9: 0.31729048 | GY9: 0.33121905 | GZ9: 0.34504286 | HA9: 0.35703333 | HB9: 0.32917143 | HC9: 0.3204381 | HD9: 0.30471905 | HE9: 0.29591429 | HF9: 0.30643333 | HG9: 0.35649524 | HH9: 0.44644762 | HI9: 0.45770476 | HJ9: 0.42669524 | HK9: 0.3728381 | HL9: 0.29325714 | HM9: 0.26464762 | HN9: 0.22529524 | HO9: 0.20286667 | HP9: 0.19006667 | HQ9: 0.18591429 | HR9: 0.19121905 | HS9: 0.20730476 | HT9: 0.24430476 | HU9: 0.29817143 | HV9: 0.34100952 | HW9: 0.3484 | HX9: 0.35819048 | HY9: 0.36694286 | HZ9: 0.33268571 | IA9: 0.31910476 | IB9: 0.30306667 | IC9: 0.30124762 | ID9: 0.33244762 | IE9: 0.41241905 | IF9: 0.48840952 | IG9: 0.46414286 | IH9: 0.42230476 | II9: 0.35827619 | IJ9: 0.33091429 | IK9: 0.2948 | IL9: 0.25213333 | IM9: 0.22580952 | IN9: 0.21340952 | IO9: 0.20939048 | IP9: 0.21822857 | IQ9: 0.24072381 | IR9: 0.28250476 | IS9: 0.34405714 | IT9: 0.39237143 | IU9: 0.40294286 | IV9: 0.41650476 | IW9: 0.4293619 | IX9: 0.39339048 | IY9: 0.38667619 | IZ9: 0.38271429 | JA9: 0.41549524 | JB9: 0.47800952 | JC9: 0.53834286 | JD9: 0.57913333 | JE9: 0.54524762 | JF9: 0.49212381 | JG9: 0.4116381 | JH9: 0.39069524 | JI9: 0.3458 | JJ9: 0.29592381 | JK9: 0.26457143 | JL9: 0.24871905 | JM9: 0.24417143 | JN9: 0.25572857 | JO9: 0.2843 | JP9: 0.33261905 | JQ9: 0.41265238 | JR9: 0.48758095 | JS9: 0.52445238 | JT9: 0.55024286 | JU9: 0.55467619 | JV9: 0.49535238 | JW9: 0.48271905 | JX9: 0.48399048 | JY9: 0.50811905 | JZ9: 0.54809048 | KA9: 0.58726667 | KB9: 0.62579524 | KC9: 0.5989619 | KD9: 0.55054286 | KE9: 0.47299048
A10: Giorno_feriale | B10: 0.44414762 | C10: 0.35825714 | D10: 0.30866667 | E10: 0.28522381 | F10: 0.27735238 | G10: 0.27778095 | H10: 0.30289048 | I10: 0.38282381 | J10: 0.4694 | K10: 0.46455238 | L10: 0.44709524 | M10: 0.42779048 | N10: 0.42621429 | O10: 0.44728095 | P10: 0.45227143 | Q10: 0.45369048 | R10: 0.45152857 | S10: 0.48764762 | T10: 0.57294286 | U10: 0.6709619 | V10: 0.74202381 | W10: 0.70855238 | X10: 0.65165714 | Y10: 0.54985238 | AA10: 0.40858571 | AB10: 0.33127143 | AC10: 0.28373333 | AD10: 0.2623381 | AE10: 0.25499048 | AF10: 0.25640476 | AG10: 0.2863 | AH10: 0.37385238 | AI10: 0.44777143 | AJ10: 0.41075714 | AK10: 0.38007143 | AL10: 0.35177619 | AM10: 0.34955238 | AN10: 0.36701905 | AO10: 0.37331429 | AP10: 0.37390476 | AQ10: 0.36755238 | AR10: 0.38978095 | AS10: 0.47229048 | AT10: 0.60324762 | AU10: 0.69363333 | AV10: 0.65969524 | AW10: 0.60793333 | AX10: 0.5108619 | AZ10: 0.37807619 | BA10: 0.30400476 | BB10: 0.26134762 | BC10: 0.24269524 | BD10: 0.2355 | BE10: 0.23717619 | BF10: 0.2609619 | BG10: 0.33873333 | BH10: 0.3978 | BI10: 0.36479524 | BJ10: 0.33884762 | BK10: 0.31639524 | BL10: 0.31800476 | BM10: 0.33804286 | BN10: 0.34224286 | BO10: 0.34 | BP10: 0.32789048 | BQ10: 0.32927143 | BR10: 0.38137143 | BS10: 0.51385238 | BT10: 0.63895714 | BU10: 0.62020952 | BV10: 0.57482381 | BW10: 0.47695238 | BX10: 0.35795714 | BY10: 0.28382857 | BZ10: 0.2406381 | CA10: 0.2212619 | CB10: 0.21361905 | CC10: 0.21362381 | CD10: 0.23134286 | CE10: 0.29634762 | CF10: 0.3566381 | CG10: 0.3354381 | CH10: 0.31498095 | CI10: 0.29478571 | CJ10: 0.29756667 | CK10: 0.31944762 | CL10: 0.32387143 | CM10: 0.3197 | CN10: 0.3021381 | CO10: 0.29076667 | CP10: 0.3107619 | CQ10: 0.39096667 | CR10: 0.53012381 | CS10: 0.57067143 | CT10: 0.54094762 | CU10: 0.45336667 | CV10: 0.3420619 | CW10: 0.27235714 | CX10: 0.23232381 | CY10: 0.21361905 | CZ10: 0.2053 | DA10: 0.2028 | DB10: 0.21210476 | DC10: 0.24732381 | DD10: 0.29397619 | DE10: 0.28460952 | DF10: 0.27077619 | DG10: 0.25795238 | DH10: 0.26467619 | DI10: 0.2859 | DJ10: 0.29297143 | DK10: 0.2929381 | DL10: 0.28241905 | DM10: 0.27494286 | DN10: 0.28744286 | DO10: 0.34452857 | DP10: 0.44960952 | DQ10: 0.48999524 | DR10: 0.49317143 | DS10: 0.42698095 | DT10: 0.44239048 | DU10: 0.36571429 | DV10: 0.31721905 | DW10: 0.2908619 | DX10: 0.27520476 | DY10: 0.26553333 | DZ10: 0.26118571 | EA10: 0.26746667 | EB10: 0.29345238 | EC10: 0.29406667 | ED10: 0.28902381 | EE10: 0.2886619 | EF10: 0.30872381 | EG10: 0.34639048 | EH10: 0.36658571 | EI10: 0.36770952 | EJ10: 0.35817143 | EK10: 0.3573 | EL10: 0.37367619 | EM10: 0.42775714 | EN10: 0.5181381 | EO10: 0.55251429 | EP10: 0.56390952 | EQ10: 0.52168571 | ER10: 0.54055238 | ES10: 0.47147143 | ET10: 0.41478571 | EU10: 0.38080476 | EV10: 0.35767619 | EW10: 0.33971905 | EX10: 0.32640952 | EY10: 0.31295238 | EZ10: 0.31784762 | FA10: 0.31319524 | FB10: 0.3125 | FC10: 0.32196667 | FD10: 0.3552381 | FE10: 0.41187619 | FF10: 0.44876667 | FG10: 0.45588095 | FH10: 0.44995238 | FI10: 0.45122381 | FJ10: 0.47172857 | FK10: 0.53028571 | FL10: 0.6268 | FM10: 0.66347143 | FN10: 0.6717381 | FO10: 0.62630952 | FP10: 0.44179524 | FQ10: 0.38203333 | FR10: 0.3384381 | FS10: 0.31229048 | FT10: 0.29569048 | FU10: 0.28380952 | FV10: 0.27992381 | FW10: 0.27999524 | FX10: 0.28776667 | FY10: 0.29011905 | FZ10: 0.29120476 | GA10: 0.29409048 | GB10: 0.31694286 | GC10: 0.35824762 | GD10: 0.37749048 | GE10: 0.37891905 | GF10: 0.36948095 | GG10: 0.36912857 | GH10: 0.38497619 | GI10: 0.4382 | GJ10: 0.52839048 | GK10: 0.56280952 | GL10: 0.5598 | GM10: 0.51037619 | GN10: 0.3228381 | GO10: 0.26821905 | GP10: 0.23310952 | GQ10: 0.21564762 | GR10: 0.2071 | GS10: 0.20382381 | GT10: 0.21238571 | GU10: 0.25270952 | GV10: 0.29037619 | GW10: 0.27526667 | GX10: 0.26351905 | GY10: 0.25369524 | GZ10: 0.26197143 | HA10: 0.28474762 | HB10: 0.29110476 | HC10: 0.28915714 | HD10: 0.27940952 | HE10: 0.27479524 | HF10: 0.29232381 | HG10: 0.36092381 | HH10: 0.47702857 | HI10: 0.4887381 | HJ10: 0.45826667 | HK10: 0.39321905 | HL10: 0.30476667 | HM10: 0.24490952 | HN10: 0.20900476 | HO10: 0.19216667 | HP10: 0.18489048 | HQ10: 0.18312857 | HR10: 0.19490476 | HS10: 0.25092857 | HT10: 0.31158571 | HU10: 0.28403333 | HV10: 0.26293333 | HW10: 0.24702857 | HX10: 0.25079048 | HY10: 0.26955238 | HZ10: 0.27300476 | IA10: 0.27078095 | IB10: 0.26115714 | IC10: 0.25843333 | ID10: 0.29091429 | IE10: 0.39242381 | IF10: 0.50242857 | IG10: 0.48491429 | IH10: 0.44715238 | II10: 0.37683333 | IJ10: 0.35308571 | IK10: 0.2786381 | IL10: 0.2379381 | IM10: 0.21887143 | IN10: 0.21091905 | IO10: 0.21125714 | IP10: 0.23287619 | IQ10: 0.31187143 | IR10: 0.38222381 | IS10: 0.35227619 | IT10: 0.3278 | IU10: 0.3092381 | IV10: 0.31586667 | IW10: 0.33983333 | IX10: 0.34983333 | IY10: 0.35408571 | IZ10: 0.35632381 | JA10: 0.38314286 | JB10: 0.44990476 | JC10: 0.53411905 | JD10: 0.6084 | JE10: 0.58563333 | JF10: 0.53573333 | JG10: 0.44412857 | JH10: 0.40305238 | JI10: 0.32513333 | JJ10: 0.27822381 | JK10: 0.25551905 | JL10: 0.24631429 | JM10: 0.24685238 | JN10: 0.27091905 | JO10: 0.34977619 | JP10: 0.43201429 | JQ10: 0.4228619 | JR10: 0.40602857 | JS10: 0.38561905 | JT10: 0.39015714 | JU10: 0.4198 | JV10: 0.43000476 | JW10: 0.4358 | JX10: 0.4377 | JY10: 0.46199524 | JZ10: 0.51702381 | KA10: 0.58708571 | KB10: 0.65548571 | KC10: 0.63319048 | KD10: 0.58480476 | KE10: 0.49524762
A11: 3 | B11: 0.46084848 | C11: 0.37208939 | D11: 0.30670758 | E11: 0.27078485 | F11: 0.25367424 | G11: 0.24810758 | H11: 0.26140758 | I11: 0.30587273 | J11: 0.38010758 | K11: 0.42506364 | L11: 0.46402273 | M11: 0.47858333 | N11: 0.4882197 | O11: 0.52554242 | P11: 0.51675 | Q11: 0.51691818 | R11: 0.50989697 | S11: 0.51381667 | T11: 0.57839848 | U11: 0.65830909 | V11: 0.75934848 | W11: 0.72314545 | X11: 0.66314848 | Y11: 0.5695803 | AA11: 0.42342727 | AB11: 0.34267879 | AC11: 0.28267424 | AD11: 0.25026212 | AE11: 0.23486212 | AF11: 0.23065 | AG11: 0.24473788 | AH11: 0.29174394 | AI11: 0.36391667 | AJ11: 0.40127727 | AK11: 0.43314091 | AL11: 0.43992424 | AM11: 0.44446212 | AN11: 0.47706212 | AO11: 0.46429848 | AP11: 0.4651303 | AQ11: 0.45326212 | AR11: 0.44543636 | AS11: 0.49307424 | AT11: 0.59865606 | AU11: 0.70833485 | AV11: 0.67533788 | AW11: 0.61430152 | AX11: 0.52547273 | AZ11: 0.41113788 | BA11: 0.33117879 | BB11: 0.27418636 | BC11: 0.22534242 | BD11: 0.23279242 | BE11: 0.22877727 | BF11: 0.24253939 | BG11: 0.2845197 | BH11: 0.34631364 | BI11: 0.37779091 | BJ11: 0.40368182 | BK11: 0.40668788 | BL11: 0.41132424 | BM11: 0.44188182 | BN11: 0.43148788 | BO11: 0.43039545 | BP11: 0.41682424 | BQ11: 0.40131212 | BR11: 0.43299394 | BS11: 0.53609697 | BT11: 0.67450455 | BU11: 0.65548182 | BV11: 0.60041212 | BW11: 0.51310758 | BX11: 0.38579091 | BY11: 0.3084 | BZ11: 0.25358333 | CA11: 0.22550303 | CB11: 0.21311212 | CC11: 0.20885 | CD11: 0.21829848 | CE11: 0.24988182 | CF11: 0.30497273 | CG11: 0.34116061 | CH11: 0.36914848 | CI11: 0.37516061 | CJ11: 0.38023939 | CK11: 0.40560606 | CL11: 0.38954697 | CM11: 0.38403636 | CN11: 0.36911818 | CO11: 0.34624848 | CP11: 0.34919091 | CQ11: 0.39875909 | CR11: 0.53256212 | CS11: 0.58428485 | CT11: 0.54564545 | CU11: 0.47555758 | CV11: 0.36056515 | CW11: 0.29779242 | CX11: 0.2508803 | CY11: 0.22561212 | CZ11: 0.21386364 | DA11: 0.20854545 | DB11: 0.21373939 | DC11: 0.2314197 | DD11: 0.27572424 | DE11: 0.30837121 | DF11: 0.33019242 | DG11: 0.33391364 | DH11: 0.33953182 | DI11: 0.36353636 | DJ11: 0.35697273 | DK11: 0.35390909 | DL11: 0.34241364 | DM11: 0.32381515 | DN11: 0.32320303 | DO11: 0.35660909 | DP11: 0.4541803 | DQ11: 0.50173636 | DR11: 0.48819545 | DS11: 0.43604697 | DT11: 0.41674848 | DU11: 0.35055758 | DV11: 0.30314545 | DW11: 0.2743697 | DX11: 0.25875606 | DY11: 0.25075606 | DZ11: 0.25063636 | EA11: 0.25722273 | EB11: 0.28522424 | EC11: 0.31240455 | ED11: 0.33054394 | EE11: 0.33888182 | EF11: 0.35279242 | EG11: 0.38498485 | EH11: 0.39752121 | EI11: 0.40193333 | EJ11: 0.39065455 | EK11: 0.37919697 | EL11: 0.38117727 | EM11: 0.40731061 | EN11: 0.47877121 | EO11: 0.51122424 | EP11: 0.50927879 | EQ11: 0.47799545 | ER11: 0.49456515 | ES11: 0.42829545 | ET11: 0.37766212 | EU11: 0.34313939 | EV11: 0.32148788 | EW11: 0.30808636 | EX11: 0.30309394 | EY11: 0.30051061 | EZ11: 0.31483182 | FA11: 0.33575152 | FB11: 0.35721667 | FC11: 0.37692121 | FD11: 0.40513485 | FE11: 0.45363939 | FF11: 0.48389545 | FG11: 0.49598939 | FH11: 0.48509697 | FI11: 0.47212727 | FJ11: 0.47300152 | FK11: 0.49545455 | FL11: 0.55945152 | FM11: 0.58535909 | FN11: 0.58104697 | FO11: 0.55177121 | FP11: 0.41794091 | FQ11: 0.37365606 | FR11: 0.33225909 | FS11: 0.3040197 | FT11: 0.28724545 | FU11: 0.27678636 | FV11: 0.27583485 | FW11: 0.27585455 | FX11: 0.28580909 | FY11: 0.30760152 | FZ11: 0.32942576 | GA11: 0.34469242 | GB11: 0.36398333 | GC11: 0.40025606 | GD11: 0.41570455 | GE11: 0.42131667 | GF11: 0.41330909 | GG11: 0.40303333 | GH11: 0.40521818 | GI11: 0.42806818 | GJ11: 0.4923 | GK11: 0.51974242 | GL11: 0.50266061 | GM11: 0.46636212 | GN11: 0.34286818 | GO11: 0.29355606 | GP11: 0.25460909 | GQ11: 0.2323803 | GR11: 0.22022424 | GS11: 0.2143697 | GT11: 0.21854242 | GU11: 0.2357 | GV11: 0.26426818 | GW11: 0.28965758 | GX11: 0.31307727 | GY11: 0.32152576 | GZ11: 0.33167727 | HA11: 0.35821212 | HB11: 0.35448636 | HC11: 0.35165758 | HD11: 0.34239697 | HE11: 0.32750606 | HF11: 0.32974242 | HG11: 0.36646212 | HH11: 0.47023333 | HI11: 0.48795606 | HJ11: 0.45209545 | HK11: 0.40278485 | HL11: 0.32225152 | HM11: 0.26965 | HN11: 0.22737727 | HO11: 0.20462121 | HP11: 0.19334242 | HQ11: 0.18906515 | HR11: 0.19554697 | HS11: 0.22245909 | HT11: 0.27120758 | HU11: 0.2962 | HV11: 0.31464545 | HW11: 0.31440758 | HX11: 0.31681364 | HY11: 0.34118333 | HZ11: 0.33400455 | IA11: 0.32869697 | IB11: 0.31653333 | IC11: 0.30147273 | ID11: 0.31632273 | IE11: 0.38550758 | IF11: 0.50087879 | IG11: 0.48822121 | IH11: 0.44622273 | II11: 0.38890455 | IJ11: 0.36446364 | IK11: 0.29361061 | IL11: 0.24433485 | IM11: 0.2171 | IN11: 0.20379697 | IO11: 0.19961818 | IP11: 0.20985758 | IQ11: 0.24774545 | IR11: 0.30737576 | IS11: 0.33839848 | IT11: 0.36329242 | IU11: 0.36675455 | IV11: 0.37332576 | IW11: 0.40875152 | IX11: 0.4063303 | IY11: 0.40674697 | IZ11: 0.40234697 | JA11: 0.40897121 | JB11: 0.45612727 | JC11: 0.51520758 | JD11: 0.60009848 | JE11: 0.57799697 | JF11: 0.52696818 | JG11: 0.45126364 | JH11: 0.41374848 | JI11: 0.33615455 | JJ11: 0.27818485 | JK11: 0.24417727 | JL11: 0.22714848 | JM11: 0.22135455 | JN11: 0.23276061 | JO11: 0.27431515 | JP11: 0.33971515 | JQ11: 0.38261818 | JR11: 0.41783636 | JS11: 0.42917424 | JT11: 0.43860303 | JU11: 0.4728803 | JV11: 0.46512273 | JW11: 0.46568182 | JX11: 0.46897576 | JY11: 0.48077576 | JZ11: 0.52243636 | KA11: 0.57028485 | KB11: 0.64498939 | KC11: 0.62269242 | KD11: 0.57023636 | KE11: 0.49963182
A12: SAB | B12: 0.47168636 | C12: 0.37053182 | D12: 0.30417727 | E12: 0.26860909 | F12: 0.25350455 | G12: 0.24961364 | H12: 0.26371364 | I12: 0.30716818 | J12: 0.38441818 | K12: 0.44199091 | L12: 0.47961818 | M12: 0.47537273 | N12: 0.46247273 | O12: 0.49363636 | P12: 0.50965455 | Q12: 0.52255455 | R12: 0.51325 | S12: 0.51765 | T12: 0.58973636 | U12: 0.67330909 | V12: 0.77702727 | W12: 0.72324545 | X12: 0.64625455 | Y12: 0.56384091 | AA12: 0.43145909 | AB12: 0.33878636 | AC12: 0.27881364 | AD12: 0.24696364 | AE12: 0.23266818 | AF12: 0.22818182 | AG12: 0.24213182 | AH12: 0.28464091 | AI12: 0.3576 | AJ12: 0.41553182 | AK12: 0.45216364 | AL12: 0.45385455 | AM12: 0.45105909 | AN12: 0.48746364 | AO12: 0.4965 | AP12: 0.50923182 | AQ12: 0.49606364 | AR12: 0.48292273 | AS12: 0.52364091 | AT12: 0.61894091 | AU12: 0.71812727 | AV12: 0.66710909 | AW12: 0.58589091 | AX12: 0.51043182 | AZ12: 0.41392273 | BA12: 0.32912727 | BB12: 0.27221364 | BC12: 0.24412273 | BD12: 0.23119091 | BE12: 0.2282 | BF12: 0.24252273 | BG12: 0.28155909 | BH12: 0.34674545 | BI12: 0.39463636 | BJ12: 0.42166818 | BK12: 0.41252273 | BL12: 0.40730455 | BM12: 0.44217727 | BN12: 0.45002273 | BO12: 0.45935 | BP12: 0.44458636 | BQ12: 0.42578636 | BR12: 0.45846364 | BS12: 0.5598 | BT12: 0.68671818 | BU12: 0.63963182 | BV12: 0.56670455 | BW12: 0.49305455 | BX12: 0.3846 | BY12: 0.30660909 | BZ12: 0.25255455 | CA12: 0.22473636 | CB12: 0.21234545 | CC12: 0.20770909 | CD12: 0.21624545 | CE12: 0.24348182 | CF12: 0.29829091 | CG12: 0.34808182 | CH12: 0.37815455 | CI12: 0.37581818 | CJ12: 0.3737 | CK12: 0.40529091 | CL12: 0.41141818 | CM12: 0.41777273 | CN12: 0.40052727 | CO12: 0.37399091 | CP12: 0.37199091 | CQ12: 0.41758182 | CR12: 0.54364545 | CS12: 0.5767 | CT12: 0.51955455 | CU12: 0.45690909 | CV12: 0.35603636 | CW12: 0.30181364 | CX12: 0.25382273 | CY12: 0.22858636 | CZ12: 0.21662273 | DA12: 0.21092727 | DB12: 0.21555455 | DC12: 0.23171818 | DD12: 0.27781818 | DE12: 0.31964545 | DF12: 0.34144091 | DG12: 0.33883182 | DH12: 0.33826818 | DI12: 0.36847273 | DJ12: 0.37977727 | DK12: 0.38536818 | DL12: 0.37072727 | DM12: 0.34813636 | DN12: 0.34361364 | DO12: 0.37162727 | DP12: 0.45604545 | DQ12: 0.48687273 | DR12: 0.45648182 | DS12: 0.41148636 | DT12: 0.39343182 | DU12: 0.34761364 | DV12: 0.30048182 | DW12: 0.27183182 | DX12: 0.25683182 | DY12: 0.24904545 | DZ12: 0.24885909 | EA12: 0.25416818 | EB12: 0.28294545 | EC12: 0.31593182 | ED12: 0.33559545 | EE12: 0.33974545 | EF12: 0.34965455 | EG12: 0.38402727 | EH12: 0.40519091 | EI12: 0.41345 | EJ12: 0.40214545 | EK12: 0.38671818 | EL12: 0.38473636 | EM12: 0.40460455 | EN12: 0.46509545 | EO12: 0.48582727 | EP12: 0.47062273 | EQ12: 0.44009545 | ER12: 0.46242727 | ES12: 0.42339091 | ET12: 0.37298182 | EU12: 0.3388 | EV12: 0.31755455 | EW12: 0.30441818 | EX12: 0.29973636 | EY12: 0.29783636 | EZ12: 0.31412727 | FA12: 0.33881818 | FB12: 0.35967273 | FC12: 0.37506364 | FD12: 0.4002 | FE12: 0.4519 | FF12: 0.49041818 | FG12: 0.50605455 | FH12: 0.49485455 | FI12: 0.47874545 | FJ12: 0.47501818 | FK12: 0.49092727 | FL12: 0.54234545 | FM12: 0.55423636 | FN12: 0.53618182 | FO12: 0.50606364 | FP12: 0.40944545 | FQ12: 0.37388182 | FR12: 0.33204091 | FS12: 0.30391818 | FT12: 0.28704091 | FU12: 0.27648636 | FV12: 0.27553636 | FW12: 0.27526818 | FX12: 0.28647727 | FY12: 0.3116 | FZ12: 0.33356364 | GA12: 0.34558182 | GB12: 0.36225 | GC12: 0.40228636 | GD12: 0.42655 | GE12: 0.43481818 | GF12: 0.42690909 | GG12: 0.41482273 | GH12: 0.41495 | GI12: 0.43507273 | GJ12: 0.49125 | GK12: 0.51127727 | GL12: 0.48479091 | GM12: 0.45019545 | GN12: 0.33527273 | GO12: 0.29758636 | GP12: 0.25920909 | GQ12: 0.23729091 | GR12: 0.22496364 | GS12: 0.21922727 | GT12: 0.22287727 | GU12: 0.23695 | GV12: 0.26319545 | GW12: 0.29551818 | GX12: 0.31952273 | GY12: 0.32420455 | GZ12: 0.33069091 | HA12: 0.36270455 | HB12: 0.37243182 | HC12: 0.37411818 | HD12: 0.36512727 | HE12: 0.34828182 | HF12: 0.34703636 | HG12: 0.37767727 | HH12: 0.46744091 | HI12: 0.4707 | HJ12: 0.42139545 | HK12: 0.37916364 | HL12: 0.32251818 | HM12: 0.27062727 | HN12: 0.22729091 | HO12: 0.20462727 | HP12: 0.19424545 | HQ12: 0.18975455 | HR12: 0.19588182 | HS12: 0.21963636 | HT12: 0.26831818 | HU12: 0.3056 | HV12: 0.32667273 | HW12: 0.32116364 | HX12: 0.31676364 | HY12: 0.34567273 | HZ12: 0.3558 | IA12: 0.35561818 | IB12: 0.34 | IC12: 0.31988182 | ID12: 0.32840909 | IE12: 0.39206364 | IF12: 0.50132727 | IG12: 0.47691818 | IH12: 0.42033636 | II12: 0.37287273 | IJ12: 0.36982727 | IK12: 0.29336818 | IL12: 0.24320909 | IM12: 0.21645455 | IN12: 0.20320909 | IO12: 0.19867273 | IP12: 0.20837727 | IQ12: 0.24107273 | IR12: 0.30227727 | IS12: 0.35067727 | IT12: 0.38357273 | IU12: 0.38509091 | IV12: 0.38938182 | IW12: 0.43494091 | IX12: 0.45271364 | IY12: 0.45853636 | IZ12: 0.44866818 | JA12: 0.44637273 | JB12: 0.48397727 | JC12: 0.53179545 | JD12: 0.60690909 | JE12: 0.56500909 | JF12: 0.49786364 | JG12: 0.43515 | JH12: 0.41980909 | JI12: 0.33424545 | JJ12: 0.27558182 | JK12: 0.24221818 | JL12: 0.22576364 | JM12: 0.21971818 | JN12: 0.23 | JO12: 0.26493636 | JP12: 0.3296 | JQ12: 0.38949091 | JR12: 0.43023636 | JS12: 0.43689091 | JT12: 0.44159091 | JU12: 0.48070909 | JV12: 0.49623636 | JW12: 0.51208182 | JX12: 0.51439091 | JY12: 0.52355455 | JZ12: 0.56662727 | KA12: 0.6122 | KB12: 0.66947273 | KC12: 0.61268182 | KD12: 0.54004545 | KE12: 0.48250909
A13: DOM | B13: 0.44950909 | C13: 0.39384091 | D13: 0.32776818 | E13: 0.28566818 | F13: 0.26202273 | G13: 0.25086364 | H13: 0.25699091 | I13: 0.27826818 | J13: 0.31821364 | K13: 0.38427727 | L13: 0.46889091 | M13: 0.53431818 | N13: 0.5807 | O13: 0.62863636 | P13: 0.56622727 | Q13: 0.54350455 | R13: 0.5389 | S13: 0.54011364 | T13: 0.59455 | U13: 0.65947273 | V13: 0.74186818 | W13: 0.70917727 | X13: 0.6495 | Y13: 0.55617273 | AA13: 0.40871818 | AB13: 0.36016818 | AC13: 0.29928636 | AD13: 0.26129091 | AE13: 0.24112273 | AF13: 0.23366364 | AG13: 0.24105909 | AH13: 0.26549545 | AI13: 0.30936818 | AJ13: 0.38043182 | AK13: 0.4588 | AL13: 0.50114091 | AM13: 0.52403182 | AN13: 0.55858182 | AO13: 0.49232273 | AP13: 0.47440909 | AQ13: 0.46259545 | AR13: 0.45472273 | AS13: 0.49957727 | AT13: 0.60121818 | AU13: 0.69935909 | AV13: 0.66832727 | AW13: 0.60843636 | AX13: 0.51601818 | AZ13: 0.40355909 | BA13: 0.34448636 | BB13: 0.28642727 | BC13: 0.19433636 | BD13: 0.24025455 | BE13: 0.23248182 | BF13: 0.23919545 | BG13: 0.25776818 | BH13: 0.29311364 | BI13: 0.35702273 | BJ13: 0.42672273 | BK13: 0.46545455 | BL13: 0.48904545 | BM13: 0.51984545 | BN13: 0.46210455 | BO13: 0.44280455 | BP13: 0.42997273 | BQ13: 0.41336364 | BR13: 0.43958636 | BS13: 0.53433636 | BT13: 0.66220455 | BU13: 0.65455 | BV13: 0.60095909 | BW13: 0.51057727 | BX13: 0.38085 | BY13: 0.31915 | BZ13: 0.26272273 | CA13: 0.23178182 | CB13: 0.21710455 | CC13: 0.21104545 | CD13: 0.2161 | CE13: 0.23016818 | CF13: 0.26345455 | CG13: 0.32682273 | CH13: 0.39525909 | CI13: 0.43488182 | CJ13: 0.45708182 | CK13: 0.47750455 | CL13: 0.40655909 | CM13: 0.37862273 | CN13: 0.3671 | CO13: 0.34714091 | CP13: 0.34930455 | CQ13: 0.39199091 | CR13: 0.51199091 | CS13: 0.57057727 | CT13: 0.53715 | CU13: 0.46913636 | CV13: 0.35613636 | CW13: 0.3047 | CX13: 0.25892727 | CY13: 0.2308 | CZ13: 0.2171 | DA13: 0.21019091 | DB13: 0.21218182 | DC13: 0.21619091 | DD13: 0.24247273 | DE13: 0.29854545 | DF13: 0.35194545 | DG13: 0.37837273 | DH13: 0.39623636 | DI13: 0.41732727 | DJ13: 0.37160909 | DK13: 0.35245455 | DL13: 0.34298182 | DM13: 0.32488182 | DN13: 0.32400909 | DO13: 0.35494545 | DP13: 0.44606364 | DQ13: 0.49704545 | DR13: 0.48691818 | DS13: 0.43392727 | DT13: 0.42015455 | DU13: 0.34306364 | DV13: 0.30069091 | DW13: 0.27188182 | DX13: 0.25536364 | DY13: 0.24701818 | DZ13: 0.24534545 | EA13: 0.24650909 | EB13: 0.26615455 | EC13: 0.30434545 | ED13: 0.33986364 | EE13: 0.36101818 | EF13: 0.38157273 | EG13: 0.40969091 | EH13: 0.39872727 | EI13: 0.39549091 | EJ13: 0.38557273 | EK13: 0.37776364 | EL13: 0.38163636 | EM13: 0.40804545 | EN13: 0.47277273 | EO13: 0.50530909 | EP13: 0.50854545 | EQ13: 0.48081818 | ER13: 0.50614545 | ES13: 0.41971818 | ET13: 0.37694545 | EU13: 0.34332727 | EV13: 0.32093636 | EW13: 0.30721818 | EX13: 0.30099091 | EY13: 0.2941 | EZ13: 0.30181818 | FA13: 0.32987273 | FB13: 0.36645455 | FC13: 0.3999 | FD13: 0.43527273 | FE13: 0.47780909 | FF13: 0.48413636 | FG13: 0.49111818 | FH13: 0.48452727 | FI13: 0.47471818 | FJ13: 0.47868182 | FK13: 0.4997 | FL13: 0.55641818 | FM13: 0.58149091 | FN13: 0.5819 | FO13: 0.55947273 | FP13: 0.40382727 | FQ13: 0.36335455 | FR13: 0.32747273 | FS13: 0.30022727 | FT13: 0.28341818 | FU13: 0.27323636 | FV13: 0.27177273 | FW13: 0.26862727 | FX13: 0.27271818 | FY13: 0.29936364 | FZ13: 0.33263636 | GA13: 0.35933636 | GB13: 0.38474545 | GC13: 0.41390909 | GD13: 0.40565455 | GE13: 0.40382727 | GF13: 0.39901818 | GG13: 0.39033636 | GH13: 0.39346364 | GI13: 0.41337273 | GJ13: 0.46911818 | GK13: 0.49354545 | GL13: 0.47921818 | GM13: 0.44613636 | GN13: 0.34048182 | GO13: 0.29290909 | GP13: 0.256 | GQ13: 0.23249091 | GR13: 0.21908636 | GS13: 0.21185909 | GT13: 0.21411364 | GU13: 0.22093636 | GV13: 0.23692727 | GW13: 0.28096818 | GX13: 0.33051818 | GY13: 0.35804091 | GZ13: 0.37904545 | HA13: 0.40193636 | HB13: 0.36510455 | HC13: 0.35124545 | HD13: 0.34225 | HE13: 0.32636364 | HF13: 0.32745909 | HG13: 0.35947273 | HH13: 0.45435 | HI13: 0.47987273 | HJ13: 0.44801364 | HK13: 0.40001818 | HL13: 0.31536364 | HM13: 0.2785 | HN13: 0.23658182 | HO13: 0.21102727 | HP13: 0.19612727 | HQ13: 0.19077273 | HR13: 0.1944 | HS13: 0.20774545 | HT13: 0.23880909 | HU13: 0.29001818 | HV13: 0.33748182 | HW13: 0.35725455 | HX13: 0.37134545 | HY13: 0.39558182 | HZ13: 0.35229091 | IA13: 0.33410909 | IB13: 0.32232727 | IC13: 0.30886364 | ID13: 0.32671818 | IE13: 0.39199091 | IF13: 0.49374545 | IG13: 0.48367273 | IH13: 0.44399091 | II13: 0.38417273 | IJ13: 0.35180909 | IK13: 0.30389091 | IL13: 0.2553 | IM13: 0.22400909 | IN13: 0.20772727 | IO13: 0.2014 | IP13: 0.20655455 | IQ13: 0.22399091 | IR13: 0.26050909 | IS13: 0.32179091 | IT13: 0.3796 | IU13: 0.40570909 | IV13: 0.42264545 | IW13: 0.45567273 | IX13: 0.40958182 | IY13: 0.39471818 | IZ13: 0.392 | JA13: 0.40357273 | JB13: 0.45436364 | JC13: 0.51056364 | JD13: 0.5835 | JE13: 0.56609091 | JF13: 0.51856364 | JG13: 0.44129091 | JH13: 0.40402273 | JI13: 0.35035909 | JJ13: 0.29255909 | JK13: 0.25326818 | JL13: 0.2318 | JM13: 0.22294091 | JN13: 0.22885909 | JO13: 0.25162273 | JP13: 0.29235 | JQ13: 0.36250455 | JR13: 0.43913182 | JS13: 0.48523182 | JT13: 0.51312273 | JU13: 0.54367727 | JV13: 0.47797273 | JW13: 0.44976818 | JX13: 0.45795909 | JY13: 0.47438182 | JZ13: 0.50992727 | KA13: 0.54509091 | KB13: 0.61024545 | KC13: 0.60544091 | KD13: 0.56109545 | KE13: 0.49128636
